<?xml version="1.0" encoding="utf-8"?>
<!-- This URDF was automatically created by SolidWorks to URDF Exporter! Originally created by Stephen Brawner (brawner@gmail.com) 
     Commit Version: 1.5.1-0-g916b5db  Build Version: 1.5.7152.31018
     For more information, please see http://wiki.ros.org/sw_urdf_exporter -->
<robot xmlns:xacro="http://www.ros.org/wiki/xacro"
  name="final">
  <link name="origin_link"/>
  <link
    name="base_link">
    <inertial>
      <origin
        xyz="-0.00491742822639352 0.00926321697461663 0.0362744796473964"
        rpy="0 0 0" />
      <mass
        value="0.743904097826017" />
      <inertia
        ixx="0.0128815665938208"
        ixy="-0.000108823075691167"
        ixz="1.09592346108527E-05"
        iyy="0.0153938926364957"
        iyz="2.60023505950379E-07"
        izz="0.0280566311336355" />
    </inertial>
    <visual>
      <origin
        xyz="0 0 0"
        rpy="0 0 0" />
      <geometry>
        <mesh
          filename="package://final_description/meshes/base_link.STL" />
      </geometry>
      <material
        name="">
        <color
          rgba="0.792156862745098 0.819607843137255 0.933333333333333 1" />
      </material>
    </visual>
    <collision>
      <origin
        xyz="0 0 0"
        rpy="0 0 0" />
      <geometry>
        <mesh
          filename="package://final_description/meshes/base_link.STL" />
      </geometry>
    </collision>
  </link>
  <link
    name="front_left_wheel_link">
    <inertial>
      <origin
        xyz="2.22044604925031E-16 0 0"
        rpy="0 0 0" />
      <mass
        value="0.575037119313078" />
      <inertia
        ixx="0.00102675759541011"
        ixy="-7.35658295478442E-21"
        ixz="-1.62630325872826E-19"
        iyy="0.00102675759541011"
        iyz="-8.25886164044585E-20"
        izz="0.0019001719590034" />
    </inertial>
    <visual>
      <origin
        xyz="0 0 0"
        rpy="0 0 0" />
      <geometry>
        <mesh
          filename="package://final_description/meshes/wheel_1.STL" />
      </geometry>
      <material
        name="">
        <color
          rgba="0.792156862745098 0.819607843137255 0.933333333333333 1" />
      </material>
    </visual>
    <collision>
      <origin
        xyz="0 0 0"
        rpy="0 0 0" />
      <geometry>
        <mesh
          filename="package://final_description/meshes/wheel_1.STL" />
      </geometry>
    </collision>
  </link>
  <joint
    name="front_left_wheel_joint"
    type="continuous">
    <origin
      xyz="0.28084 -0.28084 0.0212"
      rpy="1.5708 0 0.7854" />
    <parent
      link="base_link" />
    <child
      link="front_left_wheel_link" />
    <axis
      xyz="0 0 -1" />
  </joint>
  <link
    name="front_right_wheel_link">
    <inertial>
      <origin
        xyz="0 0 0"
        rpy="0 0 0" />
      <mass
        value="0.575037119313079" />
      <inertia
        ixx="0.00102675759541011"
        ixy="1.20419641603201E-19"
        ixz="3.25260651745651E-19"
        iyy="0.00102675759541011"
        iyz="-2.33467102916052E-19"
        izz="0.0019001719590034" />
    </inertial>
    <visual>
      <origin
        xyz="0 0 0"
        rpy="0 0 0" />
      <geometry>
        <mesh
          filename="package://final_description/meshes/wheel_2.STL" />
      </geometry>
      <material
        name="">
        <color
          rgba="0.792156862745098 0.819607843137255 0.933333333333333 1" />
      </material>
    </visual>
    <collision>
      <origin
        xyz="0 0 0"
        rpy="0 0 0" />
      <geometry>
        <mesh
          filename="package://final_description/meshes/wheel_2.STL" />
      </geometry>
    </collision>
  </link>
  <joint
    name="front_right_wheel_joint"
    type="continuous">
    <origin
      xyz="0.28084 0.28084 0.0212"
      rpy="1.5708 0 2.3562" />
    <parent
      link="base_link" />
    <child
      link="front_right_wheel_link" />
    <axis
      xyz="0 0 -1" />
  </joint>
  <link
    name="back_right_wheel_link">
    <inertial>
      <origin
        xyz="0 -1.11022302462516E-16 0"
        rpy="0 0 0" />
      <mass
        value="0.575037119313077" />
      <inertia
        ixx="0.00102675759541011"
        ixy="-3.84588227669927E-20"
        ixz="1.0842021724855E-19"
        iyy="0.00102675759541011"
        iyz="-1.16857364936532E-19"
        izz="0.00190017195900339" />
    </inertial>
    <visual>
      <origin
        xyz="0 0 0"
        rpy="0 0 0" />
      <geometry>
        <mesh
          filename="package://final_description/meshes/wheel_3.STL" />
      </geometry>
      <material
        name="">
        <color
          rgba="0.792156862745098 0.819607843137255 0.933333333333333 1" />
      </material>
    </visual>
    <collision>
      <origin
        xyz="0 0 0"
        rpy="0 0 0" />
      <geometry>
        <mesh
          filename="package://final_description/meshes/wheel_3.STL" />
      </geometry>
    </collision>
  </link>
  <joint
    name="back_right_wheel_joint"
    type="continuous">
    <origin
      xyz="-0.28084 0.28084 0.0212"
      rpy="-1.5708 0 0.7854" />
    <parent
      link="base_link" />
    <child
      link="back_right_wheel_link" />
    <axis
      xyz="0 0 -1" />
  </joint>
  <link
    name="back_left_wheel_link">
    <inertial>
      <origin
        xyz="-1.11022302462516E-16 0 -1.11022302462516E-16"
        rpy="0 0 0" />
      <mass
        value="0.575037119313077" />
      <inertia
        ixx="0.00102675759541011"
        ixy="1.71053036112385E-19"
        ixz="3.79470760369927E-19"
        iyy="0.00102675759541011"
        iyz="1.47751191306049E-19"
        izz="0.0019001719590034" />
    </inertial>
    <visual>
      <origin
        xyz="0 0 0"
        rpy="0 0 0" />
      <geometry>
        <mesh
          filename="package://final_description/meshes/wheel-4.STL" />
      </geometry>
      <material
        name="">
        <color
          rgba="0.792156862745098 0.819607843137255 0.933333333333333 1" />
      </material>
    </visual>
    <collision>
      <origin
        xyz="0 0 0"
        rpy="0 0 0" />
      <geometry>
        <mesh
          filename="package://final_description/meshes/wheel-4.STL" />
      </geometry>
    </collision>
  </link>
  <joint
    name="back_left_wheel_joint"
    type="continuous">
    <origin
      xyz="-0.28084 -0.28084 0.0212"
      rpy="1.5708 0 -0.7854" />
    <parent
      link="base_link" />
    <child
      link="back_left_wheel_link" />
    <axis
      xyz="0 0 1" />
  </joint>

  <joint name="base_joint" type="fixed">
    <parent link="origin_link" />
    <child link="base_link" />
    <origin xyz="0 0 0.02"/>
  </joint>


    <gazebo reference="front_left_wheel_link">
      <mu1 value="0.2"/>  <!--0.2-->
      <mu2 value="1.5"/>
      <kp value="10000000.0" />
      <kd value="10000.0" />
      <fdir1 value="0 0 1"/>
      <maxContacts value= "1"/>
        <material
          name="">
          <color
            rgba="0.792156862745098 0.819607843137255 0.933333333333333 1" />
        </material>
    </gazebo>

    <gazebo reference="front_right_wheel_link">
      <mu1 value="0.2"/>  <!--0.2-->
      <mu2 value="1.5"/>
      <kp value="10000000.0" />
      <kd value="10000.0" />
      <fdir1 value="0 0 1"/>
      <maxContacts value= "1"/>
        <material
          name="">
          <color
            rgba="0.792156862745098 0.819607843137255 0.933333333333333 1" />
        </material>
    </gazebo>

    <gazebo reference="back_right_wheel_link">
      <mu1 value="0.2"/>  <!--0.2-->
      <mu2 value="1.5"/>
      <kp value="10000000.0" />
      <kd value="10000.0" />
      <fdir1 value="0 0 1"/>
      <maxContacts value= "1"/>
        <material
          name="">
          <color
            rgba="0.792156862745098 0.819607843137255 0.933333333333333 1" />
        </material>
    </gazebo>

    <gazebo reference="back_left_wheel_link">
      <mu1 value="0.2"/>  <!--0.2-->
      <mu2 value="1.5"/>
      <kp value="10000000.0" />
      <kd value="10000.0" />
      <fdir1 value="0 0 1"/>
      <maxContacts value= "1"/>
        <material
          name="">
          <color
            rgba="0.792156862745098 0.819607843137255 0.933333333333333 1" />
        </material>
    </gazebo>


    <transmission name="front_left_wheel_trans" type="SimpleTransmission">
      <type>transmission_interface/SimpleTransmission</type>
      <actuator name="front_left_wheel_motor">
        <mechanicalReduction>1</mechanicalReduction>
      </actuator>
      <joint name="front_left_wheel_joint">
        <hardwareInterface>hardware_interface/VelocityJointInterface</hardwareInterface>
      </joint>
    </transmission>

    <transmission name="front_right_wheel_trans" type="SimpleTransmission">
      <type>transmission_interface/SimpleTransmission</type>
      <actuator name="front_right_wheel_motor">
        <mechanicalReduction>1</mechanicalReduction>
      </actuator>
      <joint name="front_right_wheel_joint">
        <hardwareInterface>hardware_interface/VelocityJointInterface</hardwareInterface>
      </joint>
    </transmission>

    <transmission name="back_left_wheel_trans" type="SimpleTransmission">
      <type>transmission_interface/SimpleTransmission</type>
      <actuator name="back_left_wheel_motor">
        <mechanicalReduction>1</mechanicalReduction>
      </actuator>
      <joint name="back_left_wheel_joint">
        <hardwareInterface>hardware_interface/VelocityJointInterface</hardwareInterface>
      </joint>
    </transmission>

    <transmission name="back_right_wheel_trans" type="SimpleTransmission">
      <type>transmission_interface/SimpleTransmission</type>
      <actuator name="back_right_wheel_motor">
        <mechanicalReduction>1</mechanicalReduction>
      </actuator>
      <joint name="back_right_wheel_joint">
        <hardwareInterface>hardware_interface/VelocityJointInterface</hardwareInterface>
      </joint>
    </transmission>

  <gazebo>
    <plugin name="gazebo_ros_control" filename="libgazebo_ros_control.so">
    <robotNamespace>final</robotNamespace>
    </plugin>
  </gazebo>

  <gazebo>
    <plugin name="ground_truth" filename="libgazebo_ros_p3d.so">
      <frameName>world</frameName>
      <bodyName>base_link</bodyName>
      <topicName>odom</topicName>
      <updateRate>30.0</updateRate>
    </plugin>
  </gazebo>


</robot>